Workbook
Name I18N_KEY: 'M2 · i18n'!$B$4:$B$215
Name I18N_FR: 'M2 · i18n'!$C$4:$C$215
Name I18N_EN: 'M2 · i18n'!$D$4:$D$215
Name MOIS_FR: 'M2 · i18n'!$J$4:$J$15
Name MOIS_EN: 'M2 · i18n'!$K$4:$K$15
Name P_START: 'M0 · Pilotage'!$D$12
Name P_END: 'M0 · Pilotage'!$D$13
Name PP_START: 'M0 · Pilotage'!$D$14
Name PP_END: 'M0 · Pilotage'!$D$15
Name PY_START: 'M0 · Pilotage'!$D$16
Name PY_END: 'M0 · Pilotage'!$D$17
Name LANG: 'M0 · Pilotage'!$D$4
Name GRAIN: 'M0 · Pilotage'!$D$5
Name ANNEE: 'M0 · Pilotage'!$D$6
Name MOIS: 'M0 · Pilotage'!$D$7
Name PERIODE: 'M0 · Pilotage'!$D$8
Name RAG_KEY: 'M1 · Paramètres'!$B$5:$B$126
Name RAG_SENS: 'M1 · Paramètres'!$C$5:$C$126
Name RAG_SV: 'M1 · Paramètres'!$D$5:$D$126
Name RAG_SA: 'M1 · Paramètres'!$E$5:$E$126
Name BUD_MONTHS: 'M1 · Paramètres'!$H$4:$S$4
Name HDR: 'M3 · Base mensuelle'!$D$3:$AM$3

Sheet Rapport Cosmos
C14: =IFERROR(IF(LANG="EN",INDEX(I18N_EN,MATCH("nav.title",I18N_KEY,0)),INDEX(I18N_FR,MATCH("nav.title",I18N_KEY,0))),"nav.title")
C17: =IFERROR(IF(LANG="EN",INDEX(I18N_EN,MATCH("nav.subtitle",I18N_KEY,0)),INDEX(I18N_FR,MATCH("nav.subtitle",I18N_KEY,0))),"nav.subtitle")
C21: =""&IFERROR(IF(LANG="EN",INDEX(I18N_EN,MATCH("nav.period",I18N_KEY,0)),INDEX(I18N_FR,MATCH("nav.period",I18N_KEY,0))),"nav.period")&" : "&IF(LANG="EN",INDEX(MOIS_EN,MONTH(PERIODE)),INDEX(MOIS_FR,MONTH(PERIODE)))&" "&YEAR(PERIODE)
C23: =IFERROR(IF(LANG="EN",INDEX(I18N_EN,MATCH("rag.global",I18N_KEY,0)),INDEX(I18N_FR,MATCH("rag.global",I18N_KEY,0))),"rag.global")
C43: =""&IFERROR(IF(LANG="EN",INDEX(I18N_EN,MATCH("msg.confidential",I18N_KEY,0)),INDEX(I18N_FR,MATCH("msg.confidential",I18N_KEY,0))),"msg.confidential")&" · "&IFERROR(IF(LANG="EN",INDEX(I18N_EN,MATCH("msg.version",I18N_KEY,0)),INDEX(I18N_FR,MATCH("msg.version",I18N_KEY,0))),"msg.version")&" · "&IFERROR(IF(LANG="EN",INDEX(I18N_EN,MATCH("msg.updated",I18N_KEY,0)),INDEX(I18N_FR,MATCH("msg.updated",I18N_KEY,0))),"msg.updated")&": "&TEXT(TODAY(),"yyyy-mm-dd")
C47: =" "&IFERROR(IF(LANG="EN",INDEX(I18N_EN,MATCH("nav.summary",I18N_KEY,0)),INDEX(I18N_FR,MATCH("nav.summary",I18N_KEY,0))),"nav.summary")
C49: ="◈ "&IFERROR(IF(LANG="EN",INDEX(I18N_EN,MATCH("nav.synthesis",I18N_KEY,0)),INDEX(I18N_FR,MATCH("nav.synthesis",I18N_KEY,0))),"nav.synthesis")
C50: ="2. "&IFERROR(IF(LANG="EN",INDEX(I18N_EN,MATCH("dept.rh",I18N_KEY,0)),INDEX(I18N_FR,MATCH("dept.rh",I18N_KEY,0))),"dept.rh") | I50: =IFERROR((INDEX('M3 · Base mensuelle'!$D$4:$AM$4,MATCH(P_END,HDR,0))),"")
C51: ="3. "&IFERROR(IF(LANG="EN",INDEX(I18N_EN,MATCH("dept.lease",I18N_KEY,0)),INDEX(I18N_FR,MATCH("dept.lease",I18N_KEY,0))),"dept.lease") | I51: =IFERROR((AVERAGEIFS('M3 · Base mensuelle'!$D$14:$AM$14,HDR,">="&P_START,HDR,"<="&P_END)),"")
C52: ="4. "&IFERROR(IF(LANG="EN",INDEX(I18N_EN,MATCH("dept.rec",I18N_KEY,0)),INDEX(I18N_FR,MATCH("dept.rec",I18N_KEY,0))),"dept.rec") | I52: =IFERROR((INDEX('M3 · Base mensuelle'!$D$26:$AM$26,MATCH(P_END,HDR,0)))/1000000,"")
C53: ="5. "&IFERROR(IF(LANG="EN",INDEX(I18N_EN,MATCH("dept.foot",I18N_KEY,0)),INDEX(I18N_FR,MATCH("dept.foot",I18N_KEY,0))),"dept.foot") | I53: =IFERROR((SUMIFS('M3 · Base mensuelle'!$D$44:$AM$44,HDR,">="&P_START,HDR,"<="&P_END)),"")
C54: ="6. "&IFERROR(IF(LANG="EN",INDEX(I18N_EN,MATCH("dept.mkt",I18N_KEY,0)),INDEX(I18N_FR,MATCH("dept.mkt",I18N_KEY,0))),"dept.mkt") | I54: =IFERROR((AVERAGEIFS('M3 · Base mensuelle'!$D$64:$AM$64,HDR,">="&P_START,HDR,"<="&P_END)),"")
C55: ="7. "&IFERROR(IF(LANG="EN",INDEX(I18N_EN,MATCH("dept.com",I18N_KEY,0)),INDEX(I18N_FR,MATCH("dept.com",I18N_KEY,0))),"dept.com") | I55: =IFERROR((SUMIFS('M3 · Base mensuelle'!$D$69:$AM$69,HDR,">="&P_START,HDR,"<="&P_END))/1000000,"")
C56: ="8. "&IFERROR(IF(LANG="EN",INDEX(I18N_EN,MATCH("dept.hsse",I18N_KEY,0)),INDEX(I18N_FR,MATCH("dept.hsse",I18N_KEY,0))),"dept.hsse") | I56: =IFERROR((INDEX('M3 · Base mensuelle'!$D$92:$AM$92,MATCH(P_END,HDR,0))),"")
C57: ="9. "&IFERROR(IF(LANG="EN",INDEX(I18N_EN,MATCH("dept.fac",I18N_KEY,0)),INDEX(I18N_FR,MATCH("dept.fac",I18N_KEY,0))),"dept.fac") | I57: =IFERROR((AVERAGEIFS('M3 · Base mensuelle'!$D$125:$AM$125,HDR,">="&P_START,HDR,"<="&P_END)),"")
C58: ="ⓘ "&IFERROR(IF(LANG="EN",INDEX(I18N_EN,MATCH("nav.methodo",I18N_KEY,0)),INDEX(I18N_FR,MATCH("nav.methodo",I18N_KEY,0))),"nav.methodo")
C61: =" 1. "&IFERROR(IF(LANG="EN",INDEX(I18N_EN,MATCH("nav.synthesis",I18N_KEY,0)),INDEX(I18N_FR,MATCH("nav.synthesis",I18N_KEY,0))),"nav.synthesis") | O61: ="↑ "&IFERROR(IF(LANG="EN",INDEX(I18N_EN,MATCH("nav.summary",I18N_KEY,0)),INDEX(I18N_FR,MATCH("nav.summary",I18N_KEY,0))),"nav.summary")
C63: ="▌ "&IFERROR(IF(LANG="EN",INDEX(I18N_EN,MATCH("msg.hero",I18N_KEY,0)),INDEX(I18N_FR,MATCH("msg.hero",I18N_KEY,0))),"msg.hero")
C65: =IFERROR(IF(LANG="EN",INDEX(I18N_EN,MATCH("kpi.com.total_sales",I18N_KEY,0)),INDEX(I18N_FR,MATCH("kpi.com.total_sales",I18N_KEY,0))),"kpi.com.total_sales") | E65: =IFERROR(IF(LANG="EN",INDEX(I18N_EN,MATCH("kpi.lease.occ_gla",I18N_KEY,0)),INDEX(I18N_FR,MATCH("kpi.lease.occ_gla",I18N_KEY,0))),"kpi.lease.occ_gla") | G65: =IFERROR(IF(LANG="EN",INDEX(I18N_EN,MATCH("kpi.foot.total",I18N_KEY,0)),INDEX(I18N_FR,MATCH("kpi.foot.total",I18N_KEY,0))),"kpi.foot.total") | I65: =IFERROR(IF(LANG="EN",INDEX(I18N_EN,MATCH("kpi.rec.recovery",I18N_KEY,0)),INDEX(I18N_FR,MATCH("kpi.rec.recovery",I18N_KEY,0))),"kpi.rec.recovery") | K65: =IFERROR(IF(LANG="EN",INDEX(I18N_EN,MATCH("kpi.lease.passing",I18N_KEY,0)),INDEX(I18N_FR,MATCH("kpi.lease.passing",I18N_KEY,0))),"kpi.lease.passing")
C66: =IFERROR((SUMIFS('M3 · Base mensuelle'!$D$69:$AM$69,HDR,">="&P_START,HDR,"<="&P_END))/1000000,"") | E66: =IFERROR((AVERAGEIFS('M3 · Base mensuelle'!$D$14:$AM$14,HDR,">="&P_START,HDR,"<="&P_END)),"") | G66: =IFERROR((SUMIFS('M3 · Base mensuelle'!$D$44:$AM$44,HDR,">="&P_START,HDR,"<="&P_END)),"") | I66: =IFERROR((AVERAGEIFS('M3 · Base mensuelle'!$D$32:$AM$32,HDR,">="&P_START,HDR,"<="&P_END)),"") | K66: =IFERROR((INDEX('M3 · Base mensuelle'!$D$18:$AM$18,MATCH(P_END,HDR,0)))/1000000,"")
C68: ="▌ "&IFERROR(IF(LANG="EN",INDEX(I18N_EN,MATCH("msg.heatmap",I18N_KEY,0)),INDEX(I18N_FR,MATCH("msg.heatmap",I18N_KEY,0))),"msg.heatmap")
C69: Dépt / Dept | D69: KPI | E69: Achievement
C70: =IFERROR(IF(LANG="EN",INDEX(I18N_EN,MATCH("dept.rh",I18N_KEY,0)),INDEX(I18N_FR,MATCH("dept.rh",I18N_KEY,0))),"dept.rh") | D70: =IFERROR(IF(LANG="EN",INDEX(I18N_EN,MATCH("kpi.rh.payroll_var",I18N_KEY,0)),INDEX(I18N_FR,MATCH("kpi.rh.payroll_var",I18N_KEY,0))),"kpi.rh.payroll_var") | E70: =IFERROR((AVERAGEIFS('M3 · Base mensuelle'!$D$9:$AM$9,HDR,">="&P_START,HDR,"<="&P_END)),"")
C71: =IFERROR(IF(LANG="EN",INDEX(I18N_EN,MATCH("dept.lease",I18N_KEY,0)),INDEX(I18N_FR,MATCH("dept.lease",I18N_KEY,0))),"dept.lease") | D71: =IFERROR(IF(LANG="EN",INDEX(I18N_EN,MATCH("kpi.lease.occ_gla",I18N_KEY,0)),INDEX(I18N_FR,MATCH("kpi.lease.occ_gla",I18N_KEY,0))),"kpi.lease.occ_gla") | E71: =IFERROR((AVERAGEIFS('M3 · Base mensuelle'!$D$14:$AM$14,HDR,">="&P_START,HDR,"<="&P_END)),"")
C72: =IFERROR(IF(LANG="EN",INDEX(I18N_EN,MATCH("dept.rec",I18N_KEY,0)),INDEX(I18N_FR,MATCH("dept.rec",I18N_KEY,0))),"dept.rec") | D72: =IFERROR(IF(LANG="EN",INDEX(I18N_EN,MATCH("kpi.rec.recovery",I18N_KEY,0)),INDEX(I18N_FR,MATCH("kpi.rec.recovery",I18N_KEY,0))),"kpi.rec.recovery") | E72: =IFERROR((AVERAGEIFS('M3 · Base mensuelle'!$D$32:$AM$32,HDR,">="&P_START,HDR,"<="&P_END)),"")
C73: =IFERROR(IF(LANG="EN",INDEX(I18N_EN,MATCH("dept.foot",I18N_KEY,0)),INDEX(I18N_FR,MATCH("dept.foot",I18N_KEY,0))),"dept.foot") | D73: =IFERROR(IF(LANG="EN",INDEX(I18N_EN,MATCH("kpi.foot.vs_budget",I18N_KEY,0)),INDEX(I18N_FR,MATCH("kpi.foot.vs_budget",I18N_KEY,0))),"kpi.foot.vs_budget") | E73: =IFERROR((AVERAGEIFS('M3 · Base mensuelle'!$D$45:$AM$45,HDR,">="&P_START,HDR,"<="&P_END)),"")
C74: =IFERROR(IF(LANG="EN",INDEX(I18N_EN,MATCH("dept.mkt",I18N_KEY,0)),INDEX(I18N_FR,MATCH("dept.mkt",I18N_KEY,0))),"dept.mkt") | D74: =IFERROR(IF(LANG="EN",INDEX(I18N_EN,MATCH("kpi.mkt.event_roi",I18N_KEY,0)),INDEX(I18N_FR,MATCH("kpi.mkt.event_roi",I18N_KEY,0))),"kpi.mkt.event_roi") | E74: =IFERROR((AVERAGEIFS('M3 · Base mensuelle'!$D$53:$AM$53,HDR,">="&P_START,HDR,"<="&P_END)),"")
C75: =IFERROR(IF(LANG="EN",INDEX(I18N_EN,MATCH("dept.com",I18N_KEY,0)),INDEX(I18N_FR,MATCH("dept.com",I18N_KEY,0))),"dept.com") | D75: =IFERROR(IF(LANG="EN",INDEX(I18N_EN,MATCH("kpi.com.lfl",I18N_KEY,0)),INDEX(I18N_FR,MATCH("kpi.com.lfl",I18N_KEY,0))),"kpi.com.lfl") | E75: =IFERROR((AVERAGEIFS('M3 · Base mensuelle'!$D$71:$AM$71,HDR,">="&P_START,HDR,"<="&P_END)),"")
C76: =IFERROR(IF(LANG="EN",INDEX(I18N_EN,MATCH("dept.hsse",I18N_KEY,0)),INDEX(I18N_FR,MATCH("dept.hsse",I18N_KEY,0))),"dept.hsse") | D76: =IFERROR(IF(LANG="EN",INDEX(I18N_EN,MATCH("kpi.hsse.action_close",I18N_KEY,0)),INDEX(I18N_FR,MATCH("kpi.hsse.action_close",I18N_KEY,0))),"kpi.hsse.action_close") | E76: =IFERROR((AVERAGEIFS('M3 · Base mensuelle'!$D$103:$AM$103,HDR,">="&P_START,HDR,"<="&P_END)),"")
C77: =IFERROR(IF(LANG="EN",INDEX(I18N_EN,MATCH("dept.fac",I18N_KEY,0)),INDEX(I18N_FR,MATCH("dept.fac",I18N_KEY,0))),"dept.fac") | D77: =IFERROR(IF(LANG="EN",INDEX(I18N_EN,MATCH("kpi.fac.sla",I18N_KEY,0)),INDEX(I18N_FR,MATCH("kpi.fac.sla",I18N_KEY,0))),"kpi.fac.sla") | E77: =IFERROR((AVERAGEIFS('M3 · Base mensuelle'!$D$125:$AM$125,HDR,">="&P_START,HDR,"<="&P_END)),"")
C80: =" 2. "&IFERROR(IF(LANG="EN",INDEX(I18N_EN,MATCH("dept.rh",I18N_KEY,0)),INDEX(I18N_FR,MATCH("dept.rh",I18N_KEY,0))),"dept.rh")&" · "&IF(LANG="EN",INDEX(MOIS_EN,MONTH(PERIODE)),INDEX(MOIS_FR,MONTH(PERIODE)))&" "&YEAR(PERIODE) | O80: ="↑ "&IFERROR(IF(LANG="EN",INDEX(I18N_EN,MATCH("nav.summary",I18N_KEY,0)),INDEX(I18N_FR,MATCH("nav.summary",I18N_KEY,0))),"nav.summary")
C81: =""&IFERROR(IF(LANG="EN",INDEX(I18N_EN,MATCH("nav.grain",I18N_KEY,0)),INDEX(I18N_FR,MATCH("nav.grain",I18N_KEY,0))),"nav.grain")&": "&IF(GRAIN="M",IFERROR(IF(LANG="EN",INDEX(I18N_EN,MATCH("grain.month",I18N_KEY,0)),INDEX(I18N_FR,MATCH("grain.month",I18N_KEY,0))),"grain.month"),IF(GRAIN="Q",IFERROR(IF(LANG="EN",INDEX(I18N_EN,MATCH("grain.quarter",I18N_KEY,0)),INDEX(I18N_FR,MATCH("grain.quarter",I18N_KEY,0))),"grain.quarter"),IFERROR(IF(LANG="EN",INDEX(I18N_EN,MATCH("grain.year",I18N_KEY,0)),INDEX(I18N_FR,MATCH("grain.year",I18N_KEY,0))),"grain.year")))
C84: =" "&IFERROR(IF(LANG="EN",INDEX(I18N_EN,MATCH("kpi.rh.headcount",I18N_KEY,0)),INDEX(I18N_FR,MATCH("kpi.rh.headcount",I18N_KEY,0))),"kpi.rh.headcount") | I84: =" "&IFERROR(IF(LANG="EN",INDEX(I18N_EN,MATCH("kpi.rh.fte_gap",I18N_KEY,0)),INDEX(I18N_FR,MATCH("kpi.rh.fte_gap",I18N_KEY,0))),"kpi.rh.fte_gap")
C85: =IFERROR((INDEX('M3 · Base mensuelle'!$D$4:$AM$4,MATCH(P_END,HDR,0))),"") | I85: =IFERROR((INDEX('M3 · Base mensuelle'!$D$5:$AM$5,MATCH(P_END,HDR,0))),"")
C86: =IFERROR((IFERROR((INDEX('M3 · Base mensuelle'!$D$4:$AM$4,MATCH(P_END,HDR,0))),""))/(IFERROR((INDEX('M3 · Base mensuelle'!$D$4:$AM$4,MATCH(PP_END,HDR,0))),""))-1,"") | I86: =IFERROR((IFERROR((INDEX('M3 · Base mensuelle'!$D$5:$AM$5,MATCH(P_END,HDR,0))),""))/(IFERROR((INDEX('M3 · Base mensuelle'!$D$5:$AM$5,MATCH(PP_END,HDR,0))),""))-1,"")
C89: =" "&IFERROR(IF(LANG="EN",INDEX(I18N_EN,MATCH("kpi.rh.open_pos",I18N_KEY,0)),INDEX(I18N_FR,MATCH("kpi.rh.open_pos",I18N_KEY,0))),"kpi.rh.open_pos") | I89: =" "&IFERROR(IF(LANG="EN",INDEX(I18N_EN,MATCH("kpi.rh.ttf",I18N_KEY,0)),INDEX(I18N_FR,MATCH("kpi.rh.ttf",I18N_KEY,0))),"kpi.rh.ttf")
C90: =IFERROR((INDEX('M3 · Base mensuelle'!$D$6:$AM$6,MATCH(P_END,HDR,0))),"") | I90: =IFERROR((AVERAGEIFS('M3 · Base mensuelle'!$D$7:$AM$7,HDR,">="&P_START,HDR,"<="&P_END)),"")
C91: =IFERROR((IFERROR((INDEX('M3 · Base mensuelle'!$D$6:$AM$6,MATCH(P_END,HDR,0))),""))/(IFERROR((INDEX('M3 · Base mensuelle'!$D$6:$AM$6,MATCH(PP_END,HDR,0))),""))-1,"") | I91: =IFERROR((IFERROR((AVERAGEIFS('M3 · Base mensuelle'!$D$7:$AM$7,HDR,">="&P_START,HDR,"<="&P_END)),""))/(IFERROR((AVERAGEIFS('M3 · Base mensuelle'!$D$7:$AM$7,HDR,">="&PP_START,HDR,"<="&PP_END)),""))-1,"")
C94: ="▌ "&IFERROR(IF(LANG="EN",INDEX(I18N_EN,MATCH("kpi.rh.headcount",I18N_KEY,0)),INDEX(I18N_FR,MATCH("kpi.rh.headcount",I18N_KEY,0))),"kpi.rh.headcount")&" — 12 mois / 12M"
C106: ="▌ "&IF(LANG="EN","Key gauges","Jauges clés")
...

Sheet M0 · Pilotage
B1: M0 · PUPITRE DE PILOTAGE
B2: Sélecteurs globaux — pilotent tout le classeur
B4: 🌐 Langue (LANG) | D4: FR
B5: Granularité (GRAIN) | D5: M | F5: M = Mois · Q = Trimestre · Y = Année
B6: Année (ANNEE) | D6: 2026
B7: Mois (MOIS) | D7: 6
B8: Période (PERIODE) | D8: =DATE(ANNEE,MOIS,1) | F8: Libellé : | G8: =IF(LANG="EN",INDEX(MOIS_EN,MONTH(PERIODE)),INDEX(MOIS_FR,MONTH(PERIODE)))&" "&YEAR(PERIODE)
B11: MOTEUR TEMPOREL — bornes
B12: P_START | D12: =IF(GRAIN="M",PERIODE,IF(GRAIN="Q",DATE(ANNEE,(ROUNDUP(MOIS/3,0)-1)*3+1,1),DATE(ANNEE,1,1)))
B13: P_END | D13: =IF(GRAIN="M",PERIODE,IF(GRAIN="Q",EDATE(P_START,2),DATE(ANNEE,12,1)))
B14: PP_START | D14: =IF(GRAIN="M",EDATE(P_START,-1),IF(GRAIN="Q",EDATE(P_START,-3),EDATE(P_START,-12)))
B15: PP_END | D15: =IF(GRAIN="M",EDATE(P_END,-1),IF(GRAIN="Q",EDATE(P_END,-3),EDATE(P_END,-12)))
B16: PY_START | D16: =EDATE(P_START,-12)
B17: PY_END | D17: =EDATE(P_END,-12)
B20: SUIVI DE SAISIE (mois courant)
B21: Département | C21: Complétude % | D21: État
B22: =IFERROR(IF(LANG="EN",INDEX(I18N_EN,MATCH("dept.rh",I18N_KEY,0)),INDEX(I18N_FR,MATCH("dept.rh",I18N_KEY,0))),"dept.rh") | C22: =IFERROR(COUNT(INDEX('C1 · Capital Humain'!$D$8:$AM$17,0,MATCH(PERIODE,'C1 · Capital Humain'!$D$6:$AM$6,0)))/ROWS('C1 · Capital Humain'!$C$8:$C$17),0) | D22: =IF(C22>=1,"✓",IF(C22>0,"⌛","✗"))
B23: =IFERROR(IF(LANG="EN",INDEX(I18N_EN,MATCH("dept.lease",I18N_KEY,0)),INDEX(I18N_FR,MATCH("dept.lease",I18N_KEY,0))),"dept.lease") | C23: =IFERROR(COUNT(INDEX('C2 · Lease'!$D$8:$AM$19,0,MATCH(PERIODE,'C2 · Lease'!$D$6:$AM$6,0)))/ROWS('C2 · Lease'!$C$8:$C$19),0) | D23: =IF(C23>=1,"✓",IF(C23>0,"⌛","✗"))
B24: =IFERROR(IF(LANG="EN",INDEX(I18N_EN,MATCH("dept.rec",I18N_KEY,0)),INDEX(I18N_FR,MATCH("dept.rec",I18N_KEY,0))),"dept.rec") | C24: =IFERROR(COUNT(INDEX('C3 · Recouvrement'!$D$8:$AM$25,0,MATCH(PERIODE,'C3 · Recouvrement'!$D$6:$AM$6,0)))/ROWS('C3 · Recouvrement'!$C$8:$C$25),0) | D24: =IF(C24>=1,"✓",IF(C24>0,"⌛","✗"))
B25: =IFERROR(IF(LANG="EN",INDEX(I18N_EN,MATCH("dept.foot",I18N_KEY,0)),INDEX(I18N_FR,MATCH("dept.foot",I18N_KEY,0))),"dept.foot") | C25: =IFERROR(COUNT(INDEX('C4 · Footfall'!$D$8:$AM$14,0,MATCH(PERIODE,'C4 · Footfall'!$D$6:$AM$6,0)))/ROWS('C4 · Footfall'!$C$8:$C$14),0) | D25: =IF(C25>=1,"✓",IF(C25>0,"⌛","✗"))
B26: =IFERROR(IF(LANG="EN",INDEX(I18N_EN,MATCH("dept.mkt",I18N_KEY,0)),INDEX(I18N_FR,MATCH("dept.mkt",I18N_KEY,0))),"dept.mkt") | C26: =IFERROR(COUNT(INDEX('C5 · Marketing'!$D$8:$AM$24,0,MATCH(PERIODE,'C5 · Marketing'!$D$6:$AM$6,0)))/ROWS('C5 · Marketing'!$C$8:$C$24),0) | D26: =IF(C26>=1,"✓",IF(C26>0,"⌛","✗"))
B27: =IFERROR(IF(LANG="EN",INDEX(I18N_EN,MATCH("dept.com",I18N_KEY,0)),INDEX(I18N_FR,MATCH("dept.com",I18N_KEY,0))),"dept.com") | C27: =IFERROR(COUNT(INDEX('C6 · Commercial'!$D$8:$AM$26,0,MATCH(PERIODE,'C6 · Commercial'!$D$6:$AM$6,0)))/ROWS('C6 · Commercial'!$C$8:$C$26),0) | D27: =IF(C27>=1,"✓",IF(C27>0,"⌛","✗"))
B28: =IFERROR(IF(LANG="EN",INDEX(I18N_EN,MATCH("dept.hsse",I18N_KEY,0)),INDEX(I18N_FR,MATCH("dept.hsse",I18N_KEY,0))),"dept.hsse") | C28: =IFERROR(COUNT(INDEX('C7 · HSSE'!$D$8:$AM$26,0,MATCH(PERIODE,'C7 · HSSE'!$D$6:$AM$6,0)))/ROWS('C7 · HSSE'!$C$8:$C$26),0) | D28: =IF(C28>=1,"✓",IF(C28>0,"⌛","✗"))
B29: =IFERROR(IF(LANG="EN",INDEX(I18N_EN,MATCH("dept.fac",I18N_KEY,0)),INDEX(I18N_FR,MATCH("dept.fac",I18N_KEY,0))),"dept.fac") | C29: =IFERROR(COUNT(INDEX('C8 · Facility'!$D$8:$AM$27,0,MATCH(PERIODE,'C8 · Facility'!$D$6:$AM$6,0)))/ROWS('C8 · Facility'!$C$8:$C$27),0) | D29: =IF(C29>=1,"✓",IF(C29>0,"⌛","✗"))

Sheet C1 · Capital Humain
C1: ="▌ "&IFERROR(IF(LANG="EN",INDEX(I18N_EN,MATCH("msg.collect",I18N_KEY,0)),INDEX(I18N_FR,MATCH("msg.collect",I18N_KEY,0))),"msg.collect")&" · "&IFERROR(IF(LANG="EN",INDEX(I18N_EN,MATCH("dept.rh",I18N_KEY,0)),INDEX(I18N_FR,MATCH("dept.rh",I18N_KEY,0))),"dept.rh")
C2: =IFERROR(IF(LANG="EN",INDEX(I18N_EN,MATCH("msg.help",I18N_KEY,0)),INDEX(I18N_FR,MATCH("msg.help",I18N_KEY,0))),"msg.help")
C6: KPI \ Mois | D6: =DATE(2024,1,1) | E6: =DATE(2024,2,1) | F6: =DATE(2024,3,1) | G6: =DATE(2024,4,1) | H6: =DATE(2024,5,1) | I6: =DATE(2024,6,1) | J6: =DATE(2024,7,1) | K6: =DATE(2024,8,1) | L6: =DATE(2024,9,1) | M6: =DATE(2024,10,1) | N6: =DATE(2024,11,1) | O6: =DATE(2024,12,1) | P6: =DATE(2025,1,1) | Q6: =DATE(2025,2,1) | R6: =DATE(2025,3,1) | S6: =DATE(2025,4,1) | T6: =DATE(2025,5,1) | U6: =DATE(2025,6,1) | V6: =DATE(2025,7,1) | W6: =DATE(2025,8,1) | X6: =DATE(2025,9,1) | Y6: =DATE(2025,10,1) | Z6: =DATE(2025,11,1) | AA6: =DATE(2025,12,1) | AB6: =DATE(2026,1,1) | AC6: =DATE(2026,2,1) | AD6: =DATE(2026,3,1) | AE6: =DATE(2026,4,1) | AF6: =DATE(2026,5,1) | AG6: =DATE(2026,6,1) | AH6: =DATE(2026,7,1) | AI6: =DATE(2026,8,1) | AJ6: =DATE(2026,9,1) | AK6: =DATE(2026,10,1) | AL6: =DATE(2026,11,1) | AM6: =DATE(2026,12,1)
C8: =IFERROR(IF(LANG="EN",INDEX(I18N_EN,MATCH("kpi.rh.headcount",I18N_KEY,0)),INDEX(I18N_FR,MATCH("kpi.rh.headcount",I18N_KEY,0))),"kpi.rh.headcount") | D8: 118 | E8: 119 | F8: 122 | G8: 119 | H8: 118 | I8: 120 | J8: 118 | K8: 122 | L8: 120 | M8: 121 | N8: 125 | O8: 119 | P8: 125 | Q8: 117 | R8: 126 | S8: 127 | T8: 125 | U8: 122 | V8: 128 | W8: 128 | X8: 124 | Y8: 119 | Z8: 116 | AA8: 117 | AB8: 126 | AC8: 121 | AD8: 122 | AE8: 128 | AF8: 120 | AG8: 118 | AH8: 136 | AI8: 127 | AJ8: 134 | AK8: 117 | AL8: 120 | AM8: 121
C9: =IFERROR(IF(LANG="EN",INDEX(I18N_EN,MATCH("kpi.rh.fte_gap",I18N_KEY,0)),INDEX(I18N_FR,MATCH("kpi.rh.fte_gap",I18N_KEY,0))),"kpi.rh.fte_gap") | D9: 5 | E9: 5 | F9: 5 | G9: 5 | H9: 5 | I9: 5 | J9: 5 | K9: 5 | L9: 5 | M9: 5 | N9: 5 | O9: 5 | P9: 5 | Q9: 5 | R9: 5 | S9: 5 | T9: 5 | U9: 5 | V9: 5 | W9: 5 | X9: 5 | Y9: 5 | Z9: 5 | AA9: 5 | AB9: 5 | AC9: 5 | AD9: 5 | AE9: 5 | AF9: 6 | AG9: 5 | AH9: 6 | AI9: 5 | AJ9: 5 | AK9: 5 | AL9: 5 | AM9: 5
C10: =IFERROR(IF(LANG="EN",INDEX(I18N_EN,MATCH("kpi.rh.open_pos",I18N_KEY,0)),INDEX(I18N_FR,MATCH("kpi.rh.open_pos",I18N_KEY,0))),"kpi.rh.open_pos") | D10: 6 | E10: 6 | F10: 6 | G10: 6 | H10: 6 | I10: 6 | J10: 6 | K10: 6 | L10: 6 | M10: 6 | N10: 6 | O10: 6 | P10: 6 | Q10: 6 | R10: 6 | S10: 6 | T10: 6 | U10: 6 | V10: 6 | W10: 6 | X10: 6 | Y10: 6 | Z10: 6 | AA10: 6 | AB10: 6 | AC10: 6 | AD10: 6 | AE10: 7 | AF10: 7 | AG10: 7 | AH10: 6 | AI10: 6 | AJ10: 6 | AK10: 6 | AL10: 6 | AM10: 7
C11: =IFERROR(IF(LANG="EN",INDEX(I18N_EN,MATCH("kpi.rh.ttf",I18N_KEY,0)),INDEX(I18N_FR,MATCH("kpi.rh.ttf",I18N_KEY,0))),"kpi.rh.ttf") | D11: 38 | E11: 38 | F11: 38 | G11: 39 | H11: 38 | I11: 39 | J11: 39 | K11: 37 | L11: 39 | M11: 37 | N11: 39 | O11: 39 | P11: 39 | Q11: 39 | R11: 38 | S11: 38 | T11: 39 | U11: 39 | V11: 37 | W11: 42 | X11: 37 | Y11: 39 | Z11: 42 | AA11: 38 | AB11: 41 | AC11: 41 | AD11: 40 | AE11: 41 | AF11: 41 | AG11: 37 | AH11: 37 | AI11: 38 | AJ11: 41 | AK11: 40 | AL11: 40 | AM11: 42
C12: =IFERROR(IF(LANG="EN",INDEX(I18N_EN,MATCH("kpi.rh.payroll",I18N_KEY,0)),INDEX(I18N_FR,MATCH("kpi.rh.payroll",I18N_KEY,0))),"kpi.rh.payroll") | D12: 84240713 | E12: 85802099 | F12: 84566701 | G12: 85891507 | H12: 83678097 | I12: 85878154 | J12: 87060742 | K12: 87268156 | L12: 83337336 | M12: 86611209 | N12: 88878983 | O12: 87481372 | P12: 83646757 | Q12: 89653363 | R12: 86473615 | S12: 85766198 | T12: 91395465 | U12: 90927187 | V12: 83835309 | W12: 87223228 | X12: 91602388 | Y12: 89926782 | Z12: 89409756 | AA12: 93169709 | AB12: 85755050 | AC12: 86891331 | AD12: 90960759 | AE12: 80988412 | AF12: 87303163 | AG12: 94346920 | AH12: 90363355 | AI12: 96132159 | AJ12: 94404876 | AK12: 95454123 | AL12: 95969581 | AM12: 82370360
C13: =IFERROR(IF(LANG="EN",INDEX(I18N_EN,MATCH("kpi.rh.payroll_var",I18N_KEY,0)),INDEX(I18N_FR,MATCH("kpi.rh.payroll_var",I18N_KEY,0))),"kpi.rh.payroll_var") | D13: 1.0124 | E13: 1.0225 | F13: 1.0247 | G13: 1.0286 | H13: 1.0316 | I13: 1.0374 | J13: 1.0442 | K13: 1.0071 | L13: 1.0324 | M13: 1.0376 | N13: 1.0392 | O13: 1.0201 | P13: 1.0223 | Q13: 1.0075 | R13: 1.0836 | S13: 1.0818 | T13: 1.0267 | U13: 0.9866 | V13: 1.0421 | W13: 1.0634 | X13: 1.0307 | Y13: 1.0637 | Z13: 1.0765 | AA13: 0.9985 | AB13: 1.0668 | AC13: 1.1131 | AD13: 1.0728 | AE13: 0.9926 | AF13: 1.0181 | AG13: 1.1039 | AH13: 1.054 | AI13: 1.018 | AJ13: 1.0551 | AK13: 1.0779 | AL13: 1.1303 | AM13: 0.9877
C14: =IFERROR(IF(LANG="EN",INDEX(I18N_EN,MATCH("kpi.rh.turnover",I18N_KEY,0)),INDEX(I18N_FR,MATCH("kpi.rh.turnover",I18N_KEY,0))),"kpi.rh.turnover") | D14: 0.0305 | E14: 0.0295 | F14: 0.0304 | G14: 0.0305 | H14: 0.0309 | I14: 0.0308 | J14: 0.0308 | K14: 0.0306 | L14: 0.0309 | M14: 0.0313 | N14: 0.0301 | O14: 0.0302 | P14: 0.0311 | Q14: 0.0306 | R14: 0.0293 | S14: 0.0298 | T14: 0.0304 | U14: 0.0302 | V14: 0.0309 | W14: 0.0306 | X14: 0.0302 | Y14: 0.0311 | Z14: 0.0315 | AA14: 0.0327 | AB14: 0.0299 | AC14: 0.0307 | AD14: 0.0332 | AE14: 0.0311 | AF14: 0.0315 | AG14: 0.0295 | AH14: 0.0304 | AI14: 0.0307 | AJ14: 0.0304 | AK14: 0.0308 | AL14: 0.0316 | AM14: 0.0309
C15: =IFERROR(IF(LANG="EN",INDEX(I18N_EN,MATCH("kpi.rh.absence",I18N_KEY,0)),INDEX(I18N_FR,MATCH("kpi.rh.absence",I18N_KEY,0))),"kpi.rh.absence") | D15: 0.0402 | E15: 0.0399 | F15: 0.0397 | G15: 0.0397 | H15: 0.0403 | I15: 0.0411 | J15: 0.0393 | K15: 0.0397 | L15: 0.0411 | M15: 0.0413 | N15: 0.0413 | O15: 0.0413 | P15: 0.0388 | Q15: 0.0399 | R15: 0.0406 | S15: 0.042 | T15: 0.0399 | U15: 0.0413 | V15: 0.0431 | W15: 0.0386 | X15: 0.0406 | Y15: 0.0432 | Z15: 0.0417 | AA15: 0.0425 | AB15: 0.0396 | AC15: 0.0436 | AD15: 0.04 | AE15: 0.043 | AF15: 0.0409 | AG15: 0.0414 | AH15: 0.0446 | AI15: 0.0397 | AJ15: 0.0433 | AK15: 0.0433 | AL15: 0.0445 | AM15: 0.0407
C16: =IFERROR(IF(LANG="EN",INDEX(I18N_EN,MATCH("kpi.rh.train_hours",I18N_KEY,0)),INDEX(I18N_FR,MATCH("kpi.rh.train_hours",I18N_KEY,0))),"kpi.rh.train_hours") | D16: 2.5 | E16: 2.53 | F16: 2.54 | G16: 2.48 | H16: 2.51 | I16: 2.53 | J16: 2.46 | K16: 2.53 | L16: 2.53 | M16: 2.55 | N16: 2.54 | O16: 2.51 | P16: 2.49 | Q16: 2.57 | R16: 2.6 | S16: 2.58 | T16: 2.44 | U16: 2.59 | V16: 2.58 | W16: 2.57 | X16: 2.62 | Y16: 2.61 | Z16: 2.46 | AA16: 2.44 | AB16: 2.62 | AC16: 2.45 | AD16: 2.61 | AE16: 2.78 | AF16: 2.47 | AG16: 2.45 | AH16: 2.42 | AI16: 2.6 | AJ16: 2.84 | AK16: 2.67 | AL16: 2.8 | AM16: 2.82
C17: =IFERROR(IF(LANG="EN",INDEX(I18N_EN,MATCH("kpi.rh.train_cover",I18N_KEY,0)),INDEX(I18N_FR,MATCH("kpi.rh.train_cover",I18N_KEY,0))),"kpi.rh.train_cover") | D17: 0.5986 | E17: 0.589 | F17: 0.6042 | G17: 0.6035 | H17: 0.6007 | I17: 0.5882 | J17: 0.6017 | K17: 0.6087 | L17: 0.6167 | M17: 0.6101 | N17: 0.6082 | O17: 0.6159 | P17: 0.6258 | Q17: 0.6192 | R17: 0.6343 | S17: 0.5909 | T17: 0.6143 | U17: 0.5854 | V17: 0.5835 | W17: 0.6174 | X17: 0.6037 | Y17: 0.6315 | Z17: 0.6432 | AA17: 0.6454 | AB17: 0.6442 | AC17: 0.6161 | AD17: 0.6452 | AE17: 0.6431 | AF17: 0.5873 | AG17: 0.6513 | AH17: 0.595 | AI17: 0.6514 | AJ17: 0.676 | AK17: 0.6175 | AL17: 0.5739 | AM17: 0.6027
C19: 💬 Commentaires (KPI × mois)
C20: =IFERROR(IF(LANG="EN",INDEX(I18N_EN,MATCH("kpi.rh.headcount",I18N_KEY,0)),INDEX(I18N_FR,MATCH("kpi.rh.headcount",I18N_KEY,0))),"kpi.rh.headcount")
C21: =IFERROR(IF(LANG="EN",INDEX(I18N_EN,MATCH("kpi.rh.fte_gap",I18N_KEY,0)),INDEX(I18N_FR,MATCH("kpi.rh.fte_gap",I18N_KEY,0))),"kpi.rh.fte_gap")
C22: =IFERROR(IF(LANG="EN",INDEX(I18N_EN,MATCH("kpi.rh.open_pos",I18N_KEY,0)),INDEX(I18N_FR,MATCH("kpi.rh.open_pos",I18N_KEY,0))),"kpi.rh.open_pos")
C23: =IFERROR(IF(LANG="EN",INDEX(I18N_EN,MATCH("kpi.rh.ttf",I18N_KEY,0)),INDEX(I18N_FR,MATCH("kpi.rh.ttf",I18N_KEY,0))),"kpi.rh.ttf")
C24: =IFERROR(IF(LANG="EN",INDEX(I18N_EN,MATCH("kpi.rh.payroll",I18N_KEY,0)),INDEX(I18N_FR,MATCH("kpi.rh.payroll",I18N_KEY,0))),"kpi.rh.payroll")
C25: =IFERROR(IF(LANG="EN",INDEX(I18N_EN,MATCH("kpi.rh.payroll_var",I18N_KEY,0)),INDEX(I18N_FR,MATCH("kpi.rh.payroll_var",I18N_KEY,0))),"kpi.rh.payroll_var")
C26: =IFERROR(IF(LANG="EN",INDEX(I18N_EN,MATCH("kpi.rh.turnover",I18N_KEY,0)),INDEX(I18N_FR,MATCH("kpi.rh.turnover",I18N_KEY,0))),"kpi.rh.turnover")
C27: =IFERROR(IF(LANG="EN",INDEX(I18N_EN,MATCH("kpi.rh.absence",I18N_KEY,0)),INDEX(I18N_FR,MATCH("kpi.rh.absence",I18N_KEY,0))),"kpi.rh.absence")
C28: =IFERROR(IF(LANG="EN",INDEX(I18N_EN,MATCH("kpi.rh.train_hours",I18N_KEY,0)),INDEX(I18N_FR,MATCH("kpi.rh.train_hours",I18N_KEY,0))),"kpi.rh.train_hours")
C29: =IFERROR(IF(LANG="EN",INDEX(I18N_EN,MATCH("kpi.rh.train_cover",I18N_KEY,0)),INDEX(I18N_FR,MATCH("kpi.rh.train_cover",I18N_KEY,0))),"kpi.rh.train_cover")

Sheet C2 · Lease
C1: ="▌ "&IFERROR(IF(LANG="EN",INDEX(I18N_EN,MATCH("msg.collect",I18N_KEY,0)),INDEX(I18N_FR,MATCH("msg.collect",I18N_KEY,0))),"msg.collect")&" · "&IFERROR(IF(LANG="EN",INDEX(I18N_EN,MATCH("dept.lease",I18N_KEY,0)),INDEX(I18N_FR,MATCH("dept.lease",I18N_KEY,0))),"dept.lease")
C2: =IFERROR(IF(LANG="EN",INDEX(I18N_EN,MATCH("msg.help",I18N_KEY,0)),INDEX(I18N_FR,MATCH("msg.help",I18N_KEY,0))),"msg.help")
C6: KPI \ Mois | D6: =DATE(2024,1,1) | E6: =DATE(2024,2,1) | F6: =DATE(2024,3,1) | G6: =DATE(2024,4,1) | H6: =DATE(2024,5,1) | I6: =DATE(2024,6,1) | J6: =DATE(2024,7,1) | K6: =DATE(2024,8,1) | L6: =DATE(2024,9,1) | M6: =DATE(2024,10,1) | N6: =DATE(2024,11,1) | O6: =DATE(2024,12,1) | P6: =DATE(2025,1,1) | Q6: =DATE(2025,2,1) | R6: =DATE(2025,3,1) | S6: =DATE(2025,4,1) | T6: =DATE(2025,5,1) | U6: =DATE(2025,6,1) | V6: =DATE(2025,7,1) | W6: =DATE(2025,8,1) | X6: =DATE(2025,9,1) | Y6: =DATE(2025,10,1) | Z6: =DATE(2025,11,1) | AA6: =DATE(2025,12,1) | AB6: =DATE(2026,1,1) | AC6: =DATE(2026,2,1) | AD6: =DATE(2026,3,1) | AE6: =DATE(2026,4,1) | AF6: =DATE(2026,5,1) | AG6: =DATE(2026,6,1) | AH6: =DATE(2026,7,1) | AI6: =DATE(2026,8,1) | AJ6: =DATE(2026,9,1) | AK6: =DATE(2026,10,1) | AL6: =DATE(2026,11,1) | AM6: =DATE(2026,12,1)
C8: =IFERROR(IF(LANG="EN",INDEX(I18N_EN,MATCH("kpi.lease.occ_gla",I18N_KEY,0)),INDEX(I18N_FR,MATCH("kpi.lease.occ_gla",I18N_KEY,0))),"kpi.lease.occ_gla") | D8: 0.9166 | E8: 0.9057 | F8: 0.9252 | G8: 0.8982 | H8: 0.9049 | I8: 0.9111 | J8: 0.9091 | K8: 0.9169 | L8: 0.8952 | M8: 0.8985 | N8: 0.9345 | O8: 0.9115 | P8: 0.9184 | Q8: 0.9395 | R8: 0.9081 | S8: 0.9226 | T8: 0.9132 | U8: 0.9702 | V8: 0.924 | W8: 0.8889 | X8: 0.9566 | Y8: 0.9444 | Z8: 0.9493 | AA8: 0.9294 | AB8: 0.9012 | AC8: 0.9368 | AD8: 0.8896 | AE8: 0.9273 | AF8: 1.0218 | AG8: 0.9178 | AH8: 0.9898 | AI8: 0.9747 | AJ8: 0.9159 | AK8: 1.0147 | AL8: 0.9485 | AM8: 1.0212
C9: =IFERROR(IF(LANG="EN",INDEX(I18N_EN,MATCH("kpi.lease.occ_unit",I18N_KEY,0)),INDEX(I18N_FR,MATCH("kpi.lease.occ_unit",I18N_KEY,0))),"kpi.lease.occ_unit") | D9: 0.8928 | E9: 0.8903 | F9: 0.8969 | G9: 0.8952 | H9: 0.8736 | I9: 0.906 | J9: 0.8749 | K9: 0.8847 | L9: 0.8937 | M9: 0.883 | N9: 0.8839 | O9: 0.8884 | P9: 0.8956 | Q9: 0.9196 | R9: 0.9155 | S9: 0.9225 | T9: 0.9386 | U9: 0.8619 | V9: 0.9238 | W9: 0.9375 | X9: 0.9062 | Y9: 0.9267 | Z9: 0.9126 | AA9: 0.9219 | AB9: 0.8975 | AC9: 0.9426 | AD9: 0.9714 | AE9: 0.8912 | AF9: 0.9551 | AG9: 0.9544 | AH9: 0.8572 | AI9: 1.0021 | AJ9: 0.9576 | AK9: 0.8596 | AL9: 0.9845 | AM9: 0.9723
C10: =IFERROR(IF(LANG="EN",INDEX(I18N_EN,MATCH("kpi.lease.gla_vacant",I18N_KEY,0)),INDEX(I18N_FR,MATCH("kpi.lease.gla_vacant",I18N_KEY,0))),"kpi.lease.gla_vacant") | D10: 1821 | E10: 1791 | F10: 1800 | G10: 1831 | H10: 1766 | I10: 1841 | J10: 1829 | K10: 1790 | L10: 1783 | M10: 1800 | N10: 1880 | O10: 1785 | P10: 1818 | Q10: 1847 | R10: 1825 | S10: 1784 | T10: 1819 | U10: 1862 | V10: 1923 | W10: 1954 | X10: 1810 | Y10: 1912 | Z10: 1762 | AA10: 1887 | AB10: 1830 | AC10: 1881 | AD10: 1912 | AE10: 1935 | AF10: 1942 | AG10: 1942 | AH10: 1909 | AI10: 1867 | AJ10: 1929 | AK10: 1833 | AL10: 1748 | AM10: 1938
C11: =IFERROR(IF(LANG="EN",INDEX(I18N_EN,MATCH("kpi.lease.ocr",I18N_KEY,0)),INDEX(I18N_FR,MATCH("kpi.lease.ocr",I18N_KEY,0))),"kpi.lease.ocr") | D11: 0.122 | E11: 0.1192 | F11: 0.1207 | G11: 0.1223 | H11: 0.1184 | I11: 0.1207 | J11: 0.1247 | K11: 0.1246 | L11: 0.1254 | M11: 0.1221 | N11: 0.1186 | O11: 0.1224 | P11: 0.1239 | Q11: 0.1272 | R11: 0.1174 | S11: 0.1195 | T11: 0.1254 | U11: 0.1176 | V11: 0.129 | W11: 0.1202 | X11: 0.1206 | Y11: 0.1207 | Z11: 0.1196 | AA11: 0.118 | AB11: 0.1281 | AC11: 0.1315 | AD11: 0.1271 | AE11: 0.1211 | AF11: 0.1242 | AG11: 0.1317 | AH11: 0.1222 | AI11: 0.1366 | AJ11: 0.1176 | AK11: 0.129 | AL11: 0.122 | AM11: 0.1167
C12: =IFERROR(IF(LANG="EN",INDEX(I18N_EN,MATCH("kpi.lease.passing",I18N_KEY,0)),INDEX(I18N_FR,MATCH("kpi.lease.passing",I18N_KEY,0))),"kpi.lease.passing") | D12: 129764530 | E12: 131043491 | F12: 128026818 | G12: 129862843 | H12: 129967122 | I12: 130705085 | J12: 128331991 | K12: 132330926 | L12: 131473941 | M12: 130211241 | N12: 127293641 | O12: 128312731 | P12: 131198342 | Q12: 129237143 | R12: 128958100 | S12: 126828361 | T12: 135980065 | U12: 136136023 | V12: 137129180 | W12: 128030609 | X12: 137957388 | Y12: 140226642 | Z12: 134218110 | AA12: 139915939 | AB12: 133570830 | AC12: 138048352 | AD12: 140523802 | AE12: 127169287 | AF12: 124996274 | AG12: 138504021 | AH12: 134247626 | AI12: 136220143 | AJ12: 136364731 | AK12: 142909572 | AL12: 141524616 | AM12: 140759958
C13: =IFERROR(IF(LANG="EN",INDEX(I18N_EN,MATCH("kpi.lease.erv",I18N_KEY,0)),INDEX(I18N_FR,MATCH("kpi.lease.erv",I18N_KEY,0))),"kpi.lease.erv") | D13: 138479564 | E13: 139810739 | F13: 137998064 | G13: 141348838 | H13: 138452541 | I13: 140267887 | J13: 140514594 | K13: 140478018 | L13: 143911000 | M13: 142767433 | N13: 138521663 | O13: 141837570 | P13: 146864045 | Q13: 147522063 | R13: 143093812 | S13: 142326360 | T13: 143661996 | U13: 140005861 | V13: 143163471 | W13: 146646760 | X13: 152179944 | Y13: 150185582 | Z13: 144258527 | AA13: 154340131 | AB13: 138545326 | AC13: 147984290 | AD13: 139102545 | AE13: 153760433 | AF13: 141372067 | AG13: 146261270 | AH13: 150311426 | AI13: 143320863 | AJ13: 144314297 | AK13: 154286984 | AL13: 133005441 | AM13: 138067371
C14: =IFERROR(IF(LANG="EN",INDEX(I18N_EN,MATCH("kpi.lease.reversion",I18N_KEY,0)),INDEX(I18N_FR,MATCH("kpi.lease.reversion",I18N_KEY,0))),"kpi.lease.reversion") | D14: 0.0694 | E14: 0.0701 | F14: 0.0695 | G14: 0.0695 | H14: 0.0697 | I14: 0.0708 | J14: 0.0697 | K14: 0.0707 | L14: 0.0687 | M14: 0.0688 | N14: 0.0695 | O14: 0.0696 | P14: 0.0693 | Q14: 0.0724 | R14: 0.0741 | S14: 0.0699 | T14: 0.0673 | U14: 0.0756 | V14: 0.0726 | W14: 0.0733 | X14: 0.0676 | Y14: 0.0715 | Z14: 0.0742 | AA14: 0.075 | AB14: 0.075 | AC14: 0.0735 | AD14: 0.071 | AE14: 0.0705 | AF14: 0.0691 | AG14: 0.0685 | AH14: 0.0774 | AI14: 0.0768 | AJ14: 0.0765 | AK14: 0.0678 | AL14: 0.0755 | AM14: 0.0748
C15: =IFERROR(IF(LANG="EN",INDEX(I18N_EN,MATCH("kpi.lease.vac_age",I18N_KEY,0)),INDEX(I18N_FR,MATCH("kpi.lease.vac_age",I18N_KEY,0))),"kpi.lease.vac_age") | D15: 5 | E15: 5.07 | F15: 5.1 | G15: 5.05 | H15: 5.12 | I15: 4.98 | J15: 4.96 | K15: 4.97 | L15: 4.96 | M15: 5.01 | N15: 5.01 | O15: 5.02 | P15: 5.23 | Q15: 5.09 | R15: 5.18 | S15: 5.27 | T15: 5.29 | U15: 5.03 | V15: 4.86 | W15: 5 | X15: 5.1 | Y15: 5.09 | Z15: 4.99 | AA15: 5.13 | AB15: 4.91 | AC15: 5.01 | AD15: 5.09 | AE15: 5.45 | AF15: 4.77 | AG15: 5.31 | AH15: 5.44 | AI15: 5.66 | AJ15: 5.09 | AK15: 4.87 | AL15: 5.74 | AM15: 5.16
C16: =IFERROR(IF(LANG="EN",INDEX(I18N_EN,MATCH("kpi.lease.retention",I18N_KEY,0)),INDEX(I18N_FR,MATCH("kpi.lease.retention",I18N_KEY,0))),"kpi.lease.retention") | D16: 0.7939 | E16: 0.8099 | F16: 0.8106 | G16: 0.8156 | H16: 0.8088 | I16: 0.8066 | J16: 0.7987 | K16: 0.7886 | L16: 0.8251 | M16: 0.7874 | N16: 0.8031 | O16: 0.8012 | P16: 0.8444 | Q16: 0.7822 | R16: 0.8212 | S16: 0.7979 | T16: 0.8512 | U16: 0.8327 | V16: 0.8126 | W16: 0.8286 | X16: 0.8109 | Y16: 0.8462 | Z16: 0.8225 | AA16: 0.8577 | AB16: 0.86 | AC16: 0.8952 | AD16: 0.8182 | AE16: 0.8172 | AF16: 0.9018 | AG16: 0.8615 | AH16: 0.8045 | AI16: 0.8902 | AJ16: 0.7895 | AK16: 0.8838 | AL16: 0.8725 | AM16: 0.8936
C17: =IFERROR(IF(LANG="EN",INDEX(I18N_EN,MATCH("kpi.lease.incentives",I18N_KEY,0)),INDEX(I18N_FR,MATCH("kpi.lease.incentives",I18N_KEY,0))),"kpi.lease.incentives") | D17: 6107139 | E17: 5987312 | F17: 5893230 | G17: 5980245 | H17: 6116736 | I17: 5908179 | J17: 6221458 | K17: 6165922 | L17: 5918021 | M17: 6225955 | N17: 6011200 | O17: 5956161 | P17: 5871160 | Q17: 6272439 | R17: 6235738 | S17: 5877755 | T17: 5919520 | U17: 6169520 | V17: 6034425 | W17: 6449999 | X17: 5843532 | Y17: 5908654 | Z17: 6162752 | AA17: 5972535 | AB17: 6241516 | AC17: 6517375 | AD17: 6247846 | AE17: 6696480 | AF17: 6127668 | AG17: 6498916 | AH17: 5887653 | AI17: 6535122 | AJ17: 6560637 | AK17: 6646486 | AL17: 5986834 | AM17: 6430459
C18: =IFERROR(IF(LANG="EN",INDEX(I18N_EN,MATCH("kpi.lease.rent_sqm",I18N_KEY,0)),INDEX(I18N_FR,MATCH("kpi.lease.rent_sqm",I18N_KEY,0))),"kpi.lease.rent_sqm") | D18: 9100.49 | E18: 9081.38 | F18: 9151.4 | G18: 9070.59 | H18: 8968.36 | I18: 8838.79 | J18: 9091.8 | K18: 9271.62 | L18: 9031.75 | M18: 9121.75 | N18: 9156.12 | O18: 9287.86 | P18: 8875.02 | Q18: 9515.13 | R18: 9423.33 | S18: 9556.93 | T18: 9356.43 | U18: 9343.84 | V18: 9290.05 | W18: 9460.44 | X18: 9239.55 | Y18: 8874.41 | Z18: 9100.86 | AA18: 9276.64 | AB18: 8960.59 | AC18: 9744.11 | AD18: 9919.22 | AE18: 10174.94 | AF18: 8797.56 | AG18: 9277.39 | AH18: 9825.52 | AI18: 8867.79 | AJ18: 9706.92 | AK18: 8790.08 | AL18: 9161.24 | AM18: 9608.87
C19: =IFERROR(IF(LANG="EN",INDEX(I18N_EN,MATCH("kpi.lease.walt",I18N_KEY,0)),INDEX(I18N_FR,MATCH("kpi.lease.walt",I18N_KEY,0))),"kpi.lease.walt") | D19: 3.26 | E19: 3.24 | F19: 3.22 | G19: 3.23 | H19: 3.15 | I19: 3.24 | J19: 3.22 | K19: 3.17 | L19: 3.29 | M19: 3.26 | N19: 3.2 | O19: 3.32 | P19: 3.34 | Q19: 3.18 | R19: 3.33 | S19: 3.17 | T19: 3.34 | U19: 3.41 | V19: 3.44 | W19: 3.39 | X19: 3.11 | Y19: 3.19 | Z19: 3.12 | AA19: 3.29 | AB19: 3.35 | AC19: 3.1 | AD19: 3.58 | AE19: 3.37 | AF19: 3.44 | AG19: 3.6 | AH19: 3.33 | AI19: 3.3 | AJ19: 3.53 | AK19: 3.22 | AL19: 3.37 | AM19: 3.03
C21: 💬 Commentaires (KPI × mois)
C22: =IFERROR(IF(LANG="EN",INDEX(I18N_EN,MATCH("kpi.lease.occ_gla",I18N_KEY,0)),INDEX(I18N_FR,MATCH("kpi.lease.occ_gla",I18N_KEY,0))),"kpi.lease.occ_gla")
C23: =IFERROR(IF(LANG="EN",INDEX(I18N_EN,MATCH("kpi.lease.occ_unit",I18N_KEY,0)),INDEX(I18N_FR,MATCH("kpi.lease.occ_unit",I18N_KEY,0))),"kpi.lease.occ_unit")
C24: =IFERROR(IF(LANG="EN",INDEX(I18N_EN,MATCH("kpi.lease.gla_vacant",I18N_KEY,0)),INDEX(I18N_FR,MATCH("kpi.lease.gla_vacant",I18N_KEY,0))),"kpi.lease.gla_vacant")
C25: =IFERROR(IF(LANG="EN",INDEX(I18N_EN,MATCH("kpi.lease.ocr",I18N_KEY,0)),INDEX(I18N_FR,MATCH("kpi.lease.ocr",I18N_KEY,0))),"kpi.lease.ocr")
C26: =IFERROR(IF(LANG="EN",INDEX(I18N_EN,MATCH("kpi.lease.passing",I18N_KEY,0)),INDEX(I18N_FR,MATCH("kpi.lease.passing",I18N_KEY,0))),"kpi.lease.passing")
C27: =IFERROR(IF(LANG="EN",INDEX(I18N_EN,MATCH("kpi.lease.erv",I18N_KEY,0)),INDEX(I18N_FR,MATCH("kpi.lease.erv",I18N_KEY,0))),"kpi.lease.erv")
C28: =IFERROR(IF(LANG="EN",INDEX(I18N_EN,MATCH("kpi.lease.reversion",I18N_KEY,0)),INDEX(I18N_FR,MATCH("kpi.lease.reversion",I18N_KEY,0))),"kpi.lease.reversion")
C29: =IFERROR(IF(LANG="EN",INDEX(I18N_EN,MATCH("kpi.lease.vac_age",I18N_KEY,0)),INDEX(I18N_FR,MATCH("kpi.lease.vac_age",I18N_KEY,0))),"kpi.lease.vac_age")
C30: =IFERROR(IF(LANG="EN",INDEX(I18N_EN,MATCH("kpi.lease.retention",I18N_KEY,0)),INDEX(I18N_FR,MATCH("kpi.lease.retention",I18N_KEY,0))),"kpi.lease.retention")
C31: =IFERROR(IF(LANG="EN",INDEX(I18N_EN,MATCH("kpi.lease.incentives",I18N_KEY,0)),INDEX(I18N_FR,MATCH("kpi.lease.incentives",I18N_KEY,0))),"kpi.lease.incentives")
C32: =IFERROR(IF(LANG="EN",INDEX(I18N_EN,MATCH("kpi.lease.rent_sqm",I18N_KEY,0)),INDEX(I18N_FR,MATCH("kpi.lease.rent_sqm",I18N_KEY,0))),"kpi.lease.rent_sqm")
C33: =IFERROR(IF(LANG="EN",INDEX(I18N_EN,MATCH("kpi.lease.walt",I18N_KEY,0)),INDEX(I18N_FR,MATCH("kpi.lease.walt",I18N_KEY,0))),"kpi.lease.walt")

Sheet C3 · Recouvrement
C1: ="▌ "&IFERROR(IF(LANG="EN",INDEX(I18N_EN,MATCH("msg.collect",I18N_KEY,0)),INDEX(I18N_FR,MATCH("msg.collect",I18N_KEY,0))),"msg.collect")&" · "&IFERROR(IF(LANG="EN",INDEX(I18N_EN,MATCH("dept.rec",I18N_KEY,0)),INDEX(I18N_FR,MATCH("dept.rec",I18N_KEY,0))),"dept.rec")
C2: =IFERROR(IF(LANG="EN",INDEX(I18N_EN,MATCH("msg.help",I18N_KEY,0)),INDEX(I18N_FR,MATCH("msg.help",I18N_KEY,0))),"msg.help")
C6: KPI \ Mois | D6: =DATE(2024,1,1) | E6: =DATE(2024,2,1) | F6: =DATE(2024,3,1) | G6: =DATE(2024,4,1) | H6: =DATE(2024,5,1) | I6: =DATE(2024,6,1) | J6: =DATE(2024,7,1) | K6: =DATE(2024,8,1) | L6: =DATE(2024,9,1) | M6: =DATE(2024,10,1) | N6: =DATE(2024,11,1) | O6: =DATE(2024,12,1) | P6: =DATE(2025,1,1) | Q6: =DATE(2025,2,1) | R6: =DATE(2025,3,1) | S6: =DATE(2025,4,1) | T6: =DATE(2025,5,1) | U6: =DATE(2025,6,1) | V6: =DATE(2025,7,1) | W6: =DATE(2025,8,1) | X6: =DATE(2025,9,1) | Y6: =DATE(2025,10,1) | Z6: =DATE(2025,11,1) | AA6: =DATE(2025,12,1) | AB6: =DATE(2026,1,1) | AC6: =DATE(2026,2,1) | AD6: =DATE(2026,3,1) | AE6: =DATE(2026,4,1) | AF6: =DATE(2026,5,1) | AG6: =DATE(2026,6,1) | AH6: =DATE(2026,7,1) | AI6: =DATE(2026,8,1) | AJ6: =DATE(2026,9,1) | AK6: =DATE(2026,10,1) | AL6: =DATE(2026,11,1) | AM6: =DATE(2026,12,1)
C8: =IFERROR(IF(LANG="EN",INDEX(I18N_EN,MATCH("kpi.rec.ar",I18N_KEY,0)),INDEX(I18N_FR,MATCH("kpi.rec.ar",I18N_KEY,0))),"kpi.rec.ar") | D8: 414366239 | E8: 423691166 | F8: 427868099 | G8: 430455153 | H8: 422274770 | I8: 417312958 | J8: 421323105 | K8: 418676312 | L8: 427469318 | M8: 432535261 | N8: 434277838 | O8: 433743485 | P8: 405980915 | Q8: 433503113 | R8: 437962878 | S8: 428332176 | T8: 431661017 | U8: 429290326 | V8: 435181977 | W8: 436432471 | X8: 404109244 | Y8: 429291536 | Z8: 419364308 | AA8: 427123050 | AB8: 453950966 | AC8: 457319319 | AD8: 428557449 | AE8: 423915449 | AF8: 416939134 | AG8: 405813653 | AH8: 431597129 | AI8: 426008475 | AJ8: 410165856 | AK8: 442806424 | AL8: 461841565 | AM8: 442216050
C9: =IFERROR(IF(LANG="EN",INDEX(I18N_EN,MATCH("kpi.rec.aged_0_30",I18N_KEY,0)),INDEX(I18N_FR,MATCH("kpi.rec.aged_0_30",I18N_KEY,0))),"kpi.rec.aged_0_30") | D9: 176566869 | E9: 180754297 | F9: 179423367 | G9: 177081396 | H9: 183760409 | I9: 181867277 | J9: 184268933 | K9: 184056361 | L9: 185828978 | M9: 180357436 | N9: 181095844 | O9: 180360179 | P9: 185041949 | Q9: 183918861 | R9: 183453180 | S9: 190423099 | T9: 187808866 | U9: 193882507 | V9: 179122525 | W9: 181613421 | X9: 176474070 | Y9: 184523191 | Z9: 188173308 | AA9: 182658540 | AB9: 181372484 | AC9: 191136985 | AD9: 184673556 | AE9: 189343907 | AF9: 183707360 | AG9: 184781850 | AH9: 203125223 | AI9: 199056002 | AJ9: 191009753 | AK9: 190986143 | AL9: 200624780 | AM9: 193388919
C10: =IFERROR(IF(LANG="EN",INDEX(I18N_EN,MATCH("kpi.rec.aged_30_60",I18N_KEY,0)),INDEX(I18N_FR,MATCH("kpi.rec.aged_30_60",I18N_KEY,0))),"kpi.rec.aged_30_60") | D10: 108550253 | E10: 110765082 | F10: 109193395 | G10: 108751138 | H10: 110039028 | I10: 108454050 | J10: 110466456 | K10: 111915539 | L10: 115012160 | M10: 110822489 | N10: 108008822 | O10: 111232712 | P10: 111258396 | Q10: 111185637 | R10: 110171341 | S10: 115893686 | T10: 114806144 | U10: 112493638 | V10: 110216198 | W10: 111780647 | X10: 109670201 | Y10: 110338015 | Z10: 110261812 | AA10: 121184138 | AB10: 108690120 | AC10: 116174718 | AD10: 123333770 | AE10: 123298529 | AF10: 109777540 | AG10: 117784632 | AH10: 112556017 | AI10: 113152872 | AJ10: 117709844 | AK10: 117658869 | AL10: 118197095 | AM10: 110581346
C11: =IFERROR(IF(LANG="EN",INDEX(I18N_EN,MATCH("kpi.rec.aged_60_90",I18N_KEY,0)),INDEX(I18N_FR,MATCH("kpi.rec.aged_60_90",I18N_KEY,0))),"kpi.rec.aged_60_90") | D11: 70386245 | E11: 69678240 | F11: 69255412 | G11: 69239427 | H11: 71682043 | I11: 71531905 | J11: 71445015 | K11: 71157436 | L11: 70636251 | M11: 71219063 | N11: 71394960 | O11: 73304392 | P11: 72273684 | Q11: 72379882 | R11: 75142036 | S11: 70869042 | T11: 75688264 | U11: 75651951 | V11: 68457017 | W11: 70267868 | X11: 71645972 | Y11: 72446679 | Z11: 77042300 | AA11: 71145663 | AB11: 67736393 | AC11: 71409486 | AD11: 69999000 | AE11: 76030078 | AF11: 74772953 | AG11: 78143019 | AH11: 76966664 | AI11: 68449465 | AJ11: 68158913 | AK11: 70266074 | AL11: 69406139 | AM11: 78323891
C12: =IFERROR(IF(LANG="EN",INDEX(I18N_EN,MATCH("kpi.rec.aged_90p",I18N_KEY,0)),INDEX(I18N_FR,MATCH("kpi.rec.aged_90p",I18N_KEY,0))),"kpi.rec.aged_90p") | D12: 60534918 | E12: 60287047 | F12: 59252711 | G12: 59400795 | H12: 60219192 | I12: 61594454 | J12: 59207238 | K12: 61106803 | L12: 60326024 | M12: 58808372 | N12: 61960293 | O12: 60743638 | P12: 60998592 | Q12: 61169866 | R12: 60599209 | S12: 62201183 | T12: 61568342 | U12: 59152089 | V12: 58952636 | W12: 61838800 | X12: 58900756 | Y12: 61025435 | Z12: 59863154 | AA12: 58770612 | AB12: 64485475 | AC12: 62152726 | AD12: 58195819 | AE12: 65691317 | AF12: 62160595 | AG12: 65117660 | AH12: 57521279 | AI12: 59206431 | AJ12: 66476497 | AK12: 66612596 | AL12: 62497468 | AM12: 67337932
C13: =IFERROR(IF(LANG="EN",INDEX(I18N_EN,MATCH("kpi.rec.dso",I18N_KEY,0)),INDEX(I18N_FR,MATCH("kpi.rec.dso",I18N_KEY,0))),"kpi.rec.dso") | D13: 51.83 | E13: 51.98 | F13: 53.21 | G13: 52.49 | H13: 52.57 | I13: 52.28 | J13: 51.95 | K13: 53.05 | L13: 50.9 | M13: 50.97 | N13: 53.35 | O13: 53.59 | P13: 51.67 | Q13: 53.01 | R13: 53.17 | S13: 54.33 | T13: 55.25 | U13: 50.2 | V13: 50.23 | W13: 54.39 | X13: 51.3 | Y13: 52.4 | Z13: 52.54 | AA13: 50.69 | AB13: 52.94 | AC13: 55.2 | AD13: 55.05 | AE13: 52.15 | AF13: 51.45 | AG13: 51.34 | AH13: 51.25 | AI13: 58.66 | AJ13: 55.42 | AK13: 55.39 | AL13: 59.34 | AM13: 57.2
C14: =IFERROR(IF(LANG="EN",INDEX(I18N_EN,MATCH("kpi.rec.recovery",I18N_KEY,0)),INDEX(I18N_FR,MATCH("kpi.rec.recovery",I18N_KEY,0))),"kpi.rec.recovery") | D14: 0.8479 | E14: 0.8694 | F14: 0.8742 | G14: 0.8679 | H14: 0.8852 | I14: 0.8838 | J14: 0.8565 | K14: 0.8495 | L14: 0.8901 | M14: 0.8724 | N14: 0.8727 | O14: 0.867 | P14: 0.8937 | Q14: 0.8651 | R14: 0.8947 | S14: 0.8896 | T14: 0.8822 | U14: 0.8554 | V14: 0.9098 | W14: 0.9293 | X14: 0.8629 | Y14: 0.8696 | Z14: 0.9021 | AA14: 0.8759 | AB14: 0.8647 | AC14: 0.8922 | AD14: 0.8572 | AE14: 0.9008 | AF14: 0.947 | AG14: 0.8855 | AH14: 0.8436 | AI14: 0.8766 | AJ14: 0.9089 | AK14: 0.8383 | AL14: 0.8932 | AM14: 0.9082
C15: =IFERROR(IF(LANG="EN",INDEX(I18N_EN,MATCH("kpi.rec.collected",I18N_KEY,0)),INDEX(I18N_FR,MATCH("kpi.rec.collected",I18N_KEY,0))),"kpi.rec.collected") | D15: 217864475 | E15: 224823845 | F15: 220902073 | G15: 222287409 | H15: 221532781 | I15: 225166703 | J15: 223451470 | K15: 214214491 | L15: 229918726 | M15: 227057992 | N15: 225055896 | O15: 221566342 | P15: 216416927 | Q15: 223050401 | R15: 228360254 | S15: 224290683 | T15: 215558895 | U15: 215169290 | V15: 224761666 | W15: 217193818 | X15: 233355676 | Y15: 233959761 | Z15: 212659779 | AA15: 218553820 | AB15: 235005783 | AC15: 223499599 | AD15: 225671887 | AE15: 242713168 | AF15: 238339496 | AG15: 237871379 | AH15: 235641471 | AI15: 225501376 | AJ15: 207883442 | AK15: 216737295 | AL15: 230363336 | AM15: 237047742
C16: =IFERROR(IF(LANG="EN",INDEX(I18N_EN,MATCH("kpi.rec.billed",I18N_KEY,0)),INDEX(I18N_FR,MATCH("kpi.rec.billed",I18N_KEY,0))),"kpi.rec.billed") | D16: 255287224 | E16: 251754172 | F16: 260754423 | G16: 251360691 | H16: 258317165 | I16: 260378500 | J16: 257475358 | K16: 260364730 | L16: 261501874 | M16: 260030749 | N16: 249035225 | O16: 258260719 | P16: 261477816 | Q16: 259155411 | R16: 257737467 | S16: 265371948 | T16: 267334785 | U16: 263088925 | V16: 260119976 | W16: 273460879 | X16: 265460068 | Y16: 260738183 | Z16: 261242334 | AA16: 277468008 | AB16: 271665896 | AC16: 250224454 | AD16: 277937169 | AE16: 244864949 | AF16: 275202217 | AG16: 273821551 | AH16: 243682217 | AI16: 256203183 | AJ16: 252173252 | AK16: 251467645 | AL16: 269159741 | AM16: 242099283
C17: =IFERROR(IF(LANG="EN",INDEX(I18N_EN,MATCH("kpi.rec.dunning",I18N_KEY,0)),INDEX(I18N_FR,MATCH("kpi.rec.dunning",I18N_KEY,0))),"kpi.rec.dunning") | D17: 321 | E17: 319 | F17: 319 | G17: 324 | H17: 331 | I17: 319 | J17: 317 | K17: 321 | L17: 316 | M17: 323 | N17: 314 | O17: 322 | P17: 324 | Q17: 314 | R17: 336 | S17: 334 | T17: 320 | U17: 342 | V17: 339 | W17: 328 | X17: 316 | Y17: 353 | Z17: 324 | AA17: 331 | AB17: 318 | AC17: 345 | AD17: 314 | AE17: 337 | AF17: 343 | AG17: 357 | AH17: 344 | AI17: 325 | AJ17: 357 | AK17: 330 | AL17: 341 | AM17: 349
C18: =IFERROR(IF(LANG="EN",INDEX(I18N_EN,MATCH("kpi.rec.promises",I18N_KEY,0)),INDEX(I18N_FR,MATCH("kpi.rec.promises",I18N_KEY,0))),"kpi.rec.promises") | D18: 93381068 | E18: 95323186 | F18: 95188859 | G18: 96820275 | H18: 96742369 | I18: 96800200 | J18: 96459579 | K18: 95394957 | L18: 96219189 | M18: 95207955 | N18: 99656838 | O18: 96853626 | P18: 99398115 | Q18: 92393357 | R18: 97052571 | S18: 97977258 | T18: 96286786 | U18: 100157114 | V18: 96858285 | W18: 91172062 | X18: 98556585 | Y18: 95147760 | Z18: 92991475 | AA18: 96449820 | AB18: 97944111 | AC18: 98301381 | AD18: 95213612 | AE18: 101748049 | AF18: 104669822 | AG18: 100448939 | AH18: 105978963 | AI18: 92437172 | AJ18: 102124677 | AK18: 94314135 | AL18: 94323987 | AM18: 96671485
C19: =IFERROR(IF(LANG="EN",INDEX(I18N_EN,MATCH("kpi.rec.promise_kept",I18N_KEY,0)),INDEX(I18N_FR,MATCH("kpi.rec.promise_kept",I18N_KEY,0))),"kpi.rec.promise_kept") | D19: 0.7113 | E19: 0.7182 | F19: 0.7153 | G19: 0.7351 | H19: 0.7054 | I19: 0.7238 | J19: 0.7207 | K19: 0.7308 | L19: 0.7331 | M19: 0.7361 | N19: 0.7295 | O19: 0.7503 | P19: 0.7538 | Q19: 0.7258 | R19: 0.6999 | S19: 0.7062 | T19: 0.7212 | U19: 0.7359 | V19: 0.7083 | W19: 0.7189 | X19: 0.7607 | Y19: 0.7864 | Z19: 0.7313 | AA19: 0.7247 | AB19: 0.6965 | AC19: 0.6848 | AD19: 0.7938 | AE19: 0.7482 | AF19: 0.7676 | AG19: 0.7901 | AH19: 0.6858 | AI19: 0.7792 | AJ19: 0.7244 | AK19: 0.7077 | AL19: 0.7966 | AM19: 0.752
C20: =IFERROR(IF(LANG="EN",INDEX(I18N_EN,MATCH("kpi.rec.collected_dun",I18N_KEY,0)),INDEX(I18N_FR,MATCH("kpi.rec.collected_dun",I18N_KEY,0))),"kpi.rec.collected_dun") | D20: 60660271 | E20: 59877022 | F20: 59292513 | G20: 60593628 | H20: 60060349 | I20: 61597636 | J20: 61296495 | K20: 60115942 | L20: 61408223 | M20: 62957157 | N20: 60700930 | O20: 60915970 | P20: 62214323 | Q20: 58759682 | R20: 59088437 | S20: 58661512 | T20: 60263568 | U20: 60919024 | V20: 59684366 | W20: 65125967 | X20: 61972307 | Y20: 65817617 | Z20: 66226394 | AA20: 63970393 | AB20: 64468674 | AC20: 64743169 | AD20: 64982385 | AE20: 62402525 | AF20: 59973825 | AG20: 62329081 | AH20: 65504714 | AI20: 62290833 | AJ20: 67215858 | AK20: 67508369 | AL20: 57772468 | AM20: 66346925
C21: =IFERROR(IF(LANG="EN",INDEX(I18N_EN,MATCH("kpi.rec.provision",I18N_KEY,0)),INDEX(I18N_FR,MATCH("kpi.rec.provision",I18N_KEY,0))),"kpi.rec.provision") | D21: 0.0906 | E21: 0.0885 | F21: 0.0893 | G21: 0.0892 | H21: 0.0912 | I21: 0.0905 | J21: 0.0909 | K21: 0.091 | L21: 0.0877 | M21: 0.0923 | N21: 0.0906 | O21: 0.0893 | P21: 0.0933 | Q21: 0.0916 | R21: 0.0917 | S21: 0.0945 | T21: 0.0924 | U21: 0.0925 | V21: 0.0888 | W21: 0.0913 | X21: 0.0904 | Y21: 0.0931 | Z21: 0.0912 | AA21: 0.0904 | AB21: 0.0877 | AC21: 0.099 | AD21: 0.091 | AE21: 0.0871 | AF21: 0.0955 | AG21: 0.0923 | AH21: 0.0892 | AI21: 0.0967 | AJ21: 0.1009 | AK21: 0.093 | AL21: 0.0968 | AM21: 0.099
C22: =IFERROR(IF(LANG="EN",INDEX(I18N_EN,MATCH("kpi.rec.litige_count",I18N_KEY,0)),INDEX(I18N_FR,MATCH("kpi.rec.litige_count",I18N_KEY,0))),"kpi.rec.litige_count") | D22: 14 | E22: 14 | F22: 14 | G22: 14 | H22: 14 | I22: 14 | J22: 14 | K22: 14 | L22: 14 | M22: 15 | N22: 14 | O22: 14 | P22: 14 | Q22: 14 | R22: 15 | S22: 14 | T22: 14 | U22: 15 | V22: 15 | W22: 15 | X22: 14 | Y22: 15 | Z22: 15 | AA22: 14 | AB22: 13 | AC22: 15 | AD22: 15 | AE22: 14 | AF22: 14 | AG22: 15 | AH22: 14 | AI22: 14 | AJ22: 15 | AK22: 15 | AL22: 15 | AM22: 15
C23: =IFERROR(IF(LANG="EN",INDEX(I18N_EN,MATCH("kpi.rec.litige_amount",I18N_KEY,0)),INDEX(I18N_FR,MATCH("kpi.rec.litige_amount",I18N_KEY,0))),"kpi.rec.litige_amount") | D23: 83496880 | E23: 84697690 | F23: 85567591 | G23: 85908152 | H23: 84659385 | I23: 86797143 | J23: 86289139 | K23: 86890374 | L23: 85696934 | M23: 85417832 | N23: 86404952 | O23: 86185739 | P23: 87471877 | Q23: 84546634 | R23: 85783269 | S23: 86019434 | T23: 87167239 | U23: 85139159 | V23: 83965271 | W23: 88439644 | X23: 85964028 | Y23: 90383346 | Z23: 86971843 | AA23: 85349747 | AB23: 92261282 | AC23: 93880486 | AD23: 86533019 | AE23: 87929315 | AF23: 83853924 | AG23: 86736780 | AH23: 93409483 | AI23: 94983554 | AJ23: 94477756 | AK23: 87707496 | AL23: 94236288 | AM23: 88479649
C24: =IFERROR(IF(LANG="EN",INDEX(I18N_EN,MATCH("kpi.rec.litige_resolved",I18N_KEY,0)),INDEX(I18N_FR,MATCH("kpi.rec.litige_resolved",I18N_KEY,0))),"kpi.rec.litige_resolved") | D24: 0.5514 | E24: 0.5529 | F24: 0.5534 | G24: 0.5583 | H24: 0.5581 | I24: 0.5524 | J24: 0.5434 | K24: 0.5462 | L24: 0.5731 | M24: 0.5589 | N24: 0.5705 | O24: 0.5578 | P24: 0.5548 | Q24: 0.5502 | R24: 0.5875 | S24: 0.5519 | T24: 0.583 | U24: 0.5713 | V24: 0.5819 | W24: 0.5327 | X24: 0.5765 | Y24: 0.5695 | Z24: 0.5936 | AA24: 0.5467 | AB24: 0.596 | AC24: 0.5841 | AD24: 0.5424 | AE24: 0.5521 | AF24: 0.5719 | AG24: 0.5414 | AH24: 0.5655 | AI24: 0.6132 | AJ24: 0.5507 | AK24: 0.529 | AL24: 0.6038 | AM24: 0.589
C25: =IFERROR(IF(LANG="EN",INDEX(I18N_EN,MATCH("kpi.rec.litige_age",I18N_KEY,0)),INDEX(I18N_FR,MATCH("kpi.rec.litige_age",I18N_KEY,0))),"kpi.rec.litige_age") | D25: 6.95 | E25: 6.92 | F25: 7.01 | G25: 6.98 | H25: 6.99 | I25: 7.02 | J25: 7.05 | K25: 7.14 | L25: 6.83 | M25: 7.34 | N25: 7.04 | O25: 7.09 | P25: 7.21 | Q25: 7.09 | R25: 6.75 | S25: 7.38 | T25: 7.04 | U25: 7.35 | V25: 6.84 | W25: 6.96 | X25: 7.43 | Y25: 6.87 | Z25: 6.85 | AA25: 6.88 | AB25: 7.48 | AC25: 7.3 | AD25: 7.02 | AE25: 7.2 | AF25: 6.93 | AG25: 7.05 | AH25: 7.37 | AI25: 7.77 | AJ25: 8.03 | AK25: 7.16 | AL25: 7.43 | AM25: 7.32
C27: 💬 Commentaires (KPI × mois)
C28: =IFERROR(IF(LANG="EN",INDEX(I18N_EN,MATCH("kpi.rec.ar",I18N_KEY,0)),INDEX(I18N_FR,MATCH("kpi.rec.ar",I18N_KEY,0))),"kpi.rec.ar")
C29: =IFERROR(IF(LANG="EN",INDEX(I18N_EN,MATCH("kpi.rec.aged_0_30",I18N_KEY,0)),INDEX(I18N_FR,MATCH("kpi.rec.aged_0_30",I18N_KEY,0))),"kpi.rec.aged_0_30")
C30: =IFERROR(IF(LANG="EN",INDEX(I18N_EN,MATCH("kpi.rec.aged_30_60",I18N_KEY,0)),INDEX(I18N_FR,MATCH("kpi.rec.aged_30_60",I18N_KEY,0))),"kpi.rec.aged_30_60")
C31: =IFERROR(IF(LANG="EN",INDEX(I18N_EN,MATCH("kpi.rec.aged_60_90",I18N_KEY,0)),INDEX(I18N_FR,MATCH("kpi.rec.aged_60_90",I18N_KEY,0))),"kpi.rec.aged_60_90")
C32: =IFERROR(IF(LANG="EN",INDEX(I18N_EN,MATCH("kpi.rec.aged_90p",I18N_KEY,0)),INDEX(I18N_FR,MATCH("kpi.rec.aged_90p",I18N_KEY,0))),"kpi.rec.aged_90p")
C33: =IFERROR(IF(LANG="EN",INDEX(I18N_EN,MATCH("kpi.rec.dso",I18N_KEY,0)),INDEX(I18N_FR,MATCH("kpi.rec.dso",I18N_KEY,0))),"kpi.rec.dso")
C34: =IFERROR(IF(LANG="EN",INDEX(I18N_EN,MATCH("kpi.rec.recovery",I18N_KEY,0)),INDEX(I18N_FR,MATCH("kpi.rec.recovery",I18N_KEY,0))),"kpi.rec.recovery")
C35: =IFERROR(IF(LANG="EN",INDEX(I18N_EN,MATCH("kpi.rec.collected",I18N_KEY,0)),INDEX(I18N_FR,MATCH("kpi.rec.collected",I18N_KEY,0))),"kpi.rec.collected")
C36: =IFERROR(IF(LANG="EN",INDEX(I18N_EN,MATCH("kpi.rec.billed",I18N_KEY,0)),INDEX(I18N_FR,MATCH("kpi.rec.billed",I18N_KEY,0))),"kpi.rec.billed")
C37: =IFERROR(IF(LANG="EN",INDEX(I18N_EN,MATCH("kpi.rec.dunning",I18N_KEY,0)),INDEX(I18N_FR,MATCH("kpi.rec.dunning",I18N_KEY,0))),"kpi.rec.dunning")
C38: =IFERROR(IF(LANG="EN",INDEX(I18N_EN,MATCH("kpi.rec.promises",I18N_KEY,0)),INDEX(I18N_FR,MATCH("kpi.rec.promises",I18N_KEY,0))),"kpi.rec.promises")
C39: =IFERROR(IF(LANG="EN",INDEX(I18N_EN,MATCH("kpi.rec.promise_kept",I18N_KEY,0)),INDEX(I18N_FR,MATCH("kpi.rec.promise_kept",I18N_KEY,0))),"kpi.rec.promise_kept")
C40: =IFERROR(IF(LANG="EN",INDEX(I18N_EN,MATCH("kpi.rec.collected_dun",I18N_KEY,0)),INDEX(I18N_FR,MATCH("kpi.rec.collected_dun",I18N_KEY,0))),"kpi.rec.collected_dun")
C41: =IFERROR(IF(LANG="EN",INDEX(I18N_EN,MATCH("kpi.rec.provision",I18N_KEY,0)),INDEX(I18N_FR,MATCH("kpi.rec.provision",I18N_KEY,0))),"kpi.rec.provision")
C42: =IFERROR(IF(LANG="EN",INDEX(I18N_EN,MATCH("kpi.rec.litige_count",I18N_KEY,0)),INDEX(I18N_FR,MATCH("kpi.rec.litige_count",I18N_KEY,0))),"kpi.rec.litige_count")
C43: =IFERROR(IF(LANG="EN",INDEX(I18N_EN,MATCH("kpi.rec.litige_amount",I18N_KEY,0)),INDEX(I18N_FR,MATCH("kpi.rec.litige_amount",I18N_KEY,0))),"kpi.rec.litige_amount")
C44: =IFERROR(IF(LANG="EN",INDEX(I18N_EN,MATCH("kpi.rec.litige_resolved",I18N_KEY,0)),INDEX(I18N_FR,MATCH("kpi.rec.litige_resolved",I18N_KEY,0))),"kpi.rec.litige_resolved")
C45: =IFERROR(IF(LANG="EN",INDEX(I18N_EN,MATCH("kpi.rec.litige_age",I18N_KEY,0)),INDEX(I18N_FR,MATCH("kpi.rec.litige_age",I18N_KEY,0))),"kpi.rec.litige_age")

Sheet C4 · Footfall
C1: ="▌ "&IFERROR(IF(LANG="EN",INDEX(I18N_EN,MATCH("msg.collect",I18N_KEY,0)),INDEX(I18N_FR,MATCH("msg.collect",I18N_KEY,0))),"msg.collect")&" · "&IFERROR(IF(LANG="EN",INDEX(I18N_EN,MATCH("dept.foot",I18N_KEY,0)),INDEX(I18N_FR,MATCH("dept.foot",I18N_KEY,0))),"dept.foot")
C2: =IFERROR(IF(LANG="EN",INDEX(I18N_EN,MATCH("msg.help",I18N_KEY,0)),INDEX(I18N_FR,MATCH("msg.help",I18N_KEY,0))),"msg.help")
C6: KPI \ Mois | D6: =DATE(2024,1,1) | E6: =DATE(2024,2,1) | F6: =DATE(2024,3,1) | G6: =DATE(2024,4,1) | H6: =DATE(2024,5,1) | I6: =DATE(2024,6,1) | J6: =DATE(2024,7,1) | K6: =DATE(2024,8,1) | L6: =DATE(2024,9,1) | M6: =DATE(2024,10,1) | N6: =DATE(2024,11,1) | O6: =DATE(2024,12,1) | P6: =DATE(2025,1,1) | Q6: =DATE(2025,2,1) | R6: =DATE(2025,3,1) | S6: =DATE(2025,4,1) | T6: =DATE(2025,5,1) | U6: =DATE(2025,6,1) | V6: =DATE(2025,7,1) | W6: =DATE(2025,8,1) | X6: =DATE(2025,9,1) | Y6: =DATE(2025,10,1) | Z6: =DATE(2025,11,1) | AA6: =DATE(2025,12,1) | AB6: =DATE(2026,1,1) | AC6: =DATE(2026,2,1) | AD6: =DATE(2026,3,1) | AE6: =DATE(2026,4,1) | AF6: =DATE(2026,5,1) | AG6: =DATE(2026,6,1) | AH6: =DATE(2026,7,1) | AI6: =DATE(2026,8,1) | AJ6: =DATE(2026,9,1) | AK6: =DATE(2026,10,1) | AL6: =DATE(2026,11,1) | AM6: =DATE(2026,12,1)
C8: =IFERROR(IF(LANG="EN",INDEX(I18N_EN,MATCH("kpi.foot.total",I18N_KEY,0)),INDEX(I18N_FR,MATCH("kpi.foot.total",I18N_KEY,0))),"kpi.foot.total") | D8: 476522 | E8: 487514 | F8: 474424 | G8: 486667 | H8: 495263 | I8: 482251 | J8: 482213 | K8: 498884 | L8: 485272 | M8: 485898 | N8: 492226 | O8: 504406 | P8: 479344 | Q8: 503627 | R8: 496438 | S8: 507130 | T8: 494975 | U8: 486490 | V8: 511035 | W8: 482894 | X8: 466103 | Y8: 478711 | Z8: 472979 | AA8: 469843 | AB8: 518778 | AC8: 517364 | AD8: 465397 | AE8: 534681 | AF8: 532735 | AG8: 534093 | AH8: 534931 | AI8: 463527 | AJ8: 463458 | AK8: 548845 | AL8: 549139 | AM8: 481723
C9: =IFERROR(IF(LANG="EN",INDEX(I18N_EN,MATCH("kpi.foot.vs_budget",I18N_KEY,0)),INDEX(I18N_FR,MATCH("kpi.foot.vs_budget",I18N_KEY,0))),"kpi.foot.vs_budget") | D9: 0.9866 | E9: 0.9622 | F9: 0.9612 | G9: 0.9783 | H9: 0.9762 | I9: 1.0068 | J9: 0.9939 | K9: 0.9796 | L9: 1.002 | M9: 0.995 | N9: 1.0044 | O9: 0.9729 | P9: 0.9879 | Q9: 0.979 | R9: 0.9656 | S9: 1.0174 | T9: 0.9783 | U9: 0.9532 | V9: 0.9555 | W9: 0.9394 | X9: 1.0417 | Y9: 1.0436 | Z9: 0.9875 | AA9: 0.9503 | AB9: 1.0575 | AC9: 1.0175 | AD9: 0.958 | AE9: 0.9697 | AF9: 1.0624 | AG9: 0.9523 | AH9: 1.052 | AI9: 1.0656 | AJ9: 1.0354 | AK9: 0.9944 | AL9: 1.0875 | AM9: 1.0808
C10: =IFERROR(IF(LANG="EN",INDEX(I18N_EN,MATCH("kpi.foot.per_sqm",I18N_KEY,0)),INDEX(I18N_FR,MATCH("kpi.foot.per_sqm",I18N_KEY,0))),"kpi.foot.per_sqm") | D10: 11.86 | E10: 12.09 | F10: 12.18 | G10: 11.9 | H10: 11.78 | I10: 12.27 | J10: 11.89 | K10: 11.99 | L10: 12.27 | M10: 11.74 | N10: 11.85 | O10: 12.04 | P10: 12 | Q10: 12.29 | R10: 11.87 | S10: 12.12 | T10: 12.1 | U10: 12 | V10: 11.86 | W10: 11.88 | X10: 12.37 | Y10: 12.15 | Z10: 13.13 | AA10: 12.64 | AB10: 12.9 | AC10: 12.67 | AD10: 12.58 | AE10: 12.22 | AF10: 13.36 | AG10: 12.69 | AH10: 13.22 | AI10: 12.6 | AJ10: 12.96 | AK10: 13.89 | AL10: 13.12 | AM10: 12.65
C11: =IFERROR(IF(LANG="EN",INDEX(I18N_EN,MATCH("kpi.foot.conversion",I18N_KEY,0)),INDEX(I18N_FR,MATCH("kpi.foot.conversion",I18N_KEY,0))),"kpi.foot.conversion") | D11: 0.2244 | E11: 0.2234 | F11: 0.2236 | G11: 0.2187 | H11: 0.2198 | I11: 0.2185 | J11: 0.2249 | K11: 0.2258 | L11: 0.222 | M11: 0.2188 | N11: 0.2265 | O11: 0.2333 | P11: 0.2212 | Q11: 0.2209 | R11: 0.2209 | S11: 0.2224 | T11: 0.2231 | U11: 0.2174 | V11: 0.2298 | W11: 0.2184 | X11: 0.2197 | Y11: 0.2368 | Z11: 0.2337 | AA11: 0.2347 | AB11: 0.2208 | AC11: 0.2305 | AD11: 0.237 | AE11: 0.2441 | AF11: 0.2382 | AG11: 0.2274 | AH11: 0.2151 | AI11: 0.2445 | AJ11: 0.2437 | AK11: 0.2438 | AL11: 0.2144 | AM11: 0.2281
C12: =IFERROR(IF(LANG="EN",INDEX(I18N_EN,MATCH("kpi.foot.dwell",I18N_KEY,0)),INDEX(I18N_FR,MATCH("kpi.foot.dwell",I18N_KEY,0))),"kpi.foot.dwell") | D12: 47.71 | E12: 46.36 | F12: 47.95 | G12: 46.92 | H12: 48.1 | I12: 47.64 | J12: 47.67 | K12: 45.88 | L12: 47.44 | M12: 47.52 | N12: 47.62 | O12: 47.49 | P12: 48.96 | Q12: 46.91 | R12: 46.81 | S12: 50.55 | T12: 49.04 | U12: 46.92 | V12: 46.42 | W12: 48.72 | X12: 50.83 | Y12: 48.06 | Z12: 47.59 | AA12: 48.22 | AB12: 49.39 | AC12: 47.56 | AD12: 46.95 | AE12: 50.71 | AF12: 47.36 | AG12: 49.34 | AH12: 51.54 | AI12: 50.51 | AJ12: 46.68 | AK12: 46.27 | AL12: 51.25 | AM12: 47.5
C13: =IFERROR(IF(LANG="EN",INDEX(I18N_EN,MATCH("kpi.foot.peak_share",I18N_KEY,0)),INDEX(I18N_FR,MATCH("kpi.foot.peak_share",I18N_KEY,0))),"kpi.foot.peak_share") | D13: 0.1786 | E13: 0.1818 | F13: 0.1835 | G13: 0.1824 | H13: 0.183 | I13: 0.1835 | J13: 0.1829 | K13: 0.1804 | L13: 0.1797 | M13: 0.1807 | N13: 0.1829 | O13: 0.1853 | P13: 0.1893 | Q13: 0.1859 | R13: 0.1912 | S13: 0.176 | T13: 0.1763 | U13: 0.1917 | V13: 0.1801 | W13: 0.1787 | X13: 0.1839 | Y13: 0.1833 | Z13: 0.1801 | AA13: 0.1836 | AB13: 0.1881 | AC13: 0.1918 | AD13: 0.178 | AE13: 0.1896 | AF13: 0.1823 | AG13: 0.1767 | AH13: 0.1744 | AI13: 0.1856 | AJ13: 0.2013 | AK13: 0.1838 | AL13: 0.1984 | AM13: 0.1914
C14: =IFERROR(IF(LANG="EN",INDEX(I18N_EN,MATCH("kpi.foot.weekend_share",I18N_KEY,0)),INDEX(I18N_FR,MATCH("kpi.foot.weekend_share",I18N_KEY,0))),"kpi.foot.weekend_share") | D14: 0.4117 | E14: 0.4244 | F14: 0.4241 | G14: 0.4262 | H14: 0.4204 | I14: 0.423 | J14: 0.4283 | K14: 0.4114 | L14: 0.4142 | M14: 0.4272 | N14: 0.4215 | O14: 0.4257 | P14: 0.4302 | Q14: 0.4143 | R14: 0.4258 | S14: 0.4373 | T14: 0.4254 | U14: 0.4314 | V14: 0.4559 | W14: 0.431 | X14: 0.42 | Y14: 0.4622 | Z14: 0.4235 | AA14: 0.4401 | AB14: 0.4494 | AC14: 0.4129 | AD14: 0.4372 | AE14: 0.4565 | AF14: 0.4316 | AG14: 0.4746 | AH14: 0.441 | AI14: 0.4513 | AJ14: 0.4308 | AK14: 0.4319 | AL14: 0.4585 | AM14: 0.427
C16: 💬 Commentaires (KPI × mois)
C17: =IFERROR(IF(LANG="EN",INDEX(I18N_EN,MATCH("kpi.foot.total",I18N_KEY,0)),INDEX(I18N_FR,MATCH("kpi.foot.total",I18N_KEY,0))),"kpi.foot.total")
C18: =IFERROR(IF(LANG="EN",INDEX(I18N_EN,MATCH("kpi.foot.vs_budget",I18N_KEY,0)),INDEX(I18N_FR,MATCH("kpi.foot.vs_budget",I18N_KEY,0))),"kpi.foot.vs_budget")
C19: =IFERROR(IF(LANG="EN",INDEX(I18N_EN,MATCH("kpi.foot.per_sqm",I18N_KEY,0)),INDEX(I18N_FR,MATCH("kpi.foot.per_sqm",I18N_KEY,0))),"kpi.foot.per_sqm")
C20: =IFERROR(IF(LANG="EN",INDEX(I18N_EN,MATCH("kpi.foot.conversion",I18N_KEY,0)),INDEX(I18N_FR,MATCH("kpi.foot.conversion",I18N_KEY,0))),"kpi.foot.conversion")
C21: =IFERROR(IF(LANG="EN",INDEX(I18N_EN,MATCH("kpi.foot.dwell",I18N_KEY,0)),INDEX(I18N_FR,MATCH("kpi.foot.dwell",I18N_KEY,0))),"kpi.foot.dwell")
C22: =IFERROR(IF(LANG="EN",INDEX(I18N_EN,MATCH("kpi.foot.peak_share",I18N_KEY,0)),INDEX(I18N_FR,MATCH("kpi.foot.peak_share",I18N_KEY,0))),"kpi.foot.peak_share")
C23: =IFERROR(IF(LANG="EN",INDEX(I18N_EN,MATCH("kpi.foot.weekend_share",I18N_KEY,0)),INDEX(I18N_FR,MATCH("kpi.foot.weekend_share",I18N_KEY,0))),"kpi.foot.weekend_share")

Sheet C5 · Marketing
C1: ="▌ "&IFERROR(IF(LANG="EN",INDEX(I18N_EN,MATCH("msg.collect",I18N_KEY,0)),INDEX(I18N_FR,MATCH("msg.collect",I18N_KEY,0))),"msg.collect")&" · "&IFERROR(IF(LANG="EN",INDEX(I18N_EN,MATCH("dept.mkt",I18N_KEY,0)),INDEX(I18N_FR,MATCH("dept.mkt",I18N_KEY,0))),"dept.mkt")
C2: =IFERROR(IF(LANG="EN",INDEX(I18N_EN,MATCH("msg.help",I18N_KEY,0)),INDEX(I18N_FR,MATCH("msg.help",I18N_KEY,0))),"msg.help")
